package exceptions

import kotlinx.coroutines.*
import java.io.IOException

@OptIn(DelicateCoroutinesApi::class)
fun main() = runBlocking {
    val handler = CoroutineExceptionHandler { _, exception ->
        println("CoroutineExceptionHandler got $exception with suppressed ${exception.suppressed.contentToString()}")
    }
    val job = GlobalScope.launch(handler) {
        launch {
            try {
                delay(Long.MAX_VALUE) // it gets cancelled when another sibling fails with IOException
            } catch(e: CancellationException) {
                println(e)
            } finally {
                throw ArithmeticException() // the second exception
            }
        }
        launch {
            delay(100)
            throw IOException() // the first exception
        }
        delay(Long.MAX_VALUE)
    }
    job.join()
    println("Joined failed job")
    val deferred = GlobalScope.async { // root coroutine with async
        println("Throwing exception from async")
        throw ArithmeticException() // Nothing is printed, relying on user to call await
    }
    try {
        deferred.await()
        println("Unreached")
    } catch (e: ArithmeticException) {
        println("Caught ArithmeticException from deferred.await()")
    }
}
